ExponentialRetryRequestExecuter Error: 0 : 16:45:12.6052941 : 1-vstest.console : Error while invoking '<Start>b__4' method. Current attempt: 0. Waiting 8 seconds and retrying it.
System.Net.Http.HttpRequestException: A connection attempt failed because the connected party did not properly respond after a period of time, or established connection failed because connected host has failed to respond. (192.168.0.154:8080)
 ---> System.Net.Sockets.SocketException (10060): A connection attempt failed because the connected party did not properly respond after a period of time, or established connection failed because connected host has failed to respond.
   at System.Net.Sockets.Socket.AwaitableSocketAsyncEventArgs.ThrowException(SocketError error, CancellationToken cancellationToken)
   at System.Net.Sockets.Socket.AwaitableSocketAsyncEventArgs.System.Threading.Tasks.Sources.IValueTaskSource.GetResult(Int16 token)
   at System.Net.Sockets.Socket.<ConnectAsync>g__WaitForConnectWithCancellation|277_0(AwaitableSocketAsyncEventArgs saea, ValueTask connectTask, CancellationToken cancellationToken)
   at System.Net.Http.HttpConnectionPool.ConnectToTcpHostAsync(String host, Int32 port, HttpRequestMessage initialRequest, Boolean async, CancellationToken cancellationToken)
   --- End of inner exception stack trace ---
   at System.Net.Http.HttpConnectionPool.ConnectToTcpHostAsync(String host, Int32 port, HttpRequestMessage initialRequest, Boolean async, CancellationToken cancellationToken)
   at System.Net.Http.HttpConnectionPool.ConnectAsync(HttpRequestMessage request, Boolean async, CancellationToken cancellationToken)
   at System.Net.Http.HttpConnectionPool.CreateHttp11ConnectionAsync(HttpRequestMessage request, Boolean async, CancellationToken cancellationToken)
   at System.Net.Http.HttpConnectionPool.AddHttp11ConnectionAsync(HttpRequestMessage request)
   at System.Threading.Tasks.TaskCompletionSourceWithCancellation`1.WaitWithCancellationAsync(CancellationToken cancellationToken)
   at System.Net.Http.HttpConnectionPool.GetHttp11ConnectionAsync(HttpRequestMessage request, Boolean async, CancellationToken cancellationToken)
   at System.Net.Http.HttpConnectionPool.SendWithVersionDetectionAndRetryAsync(HttpRequestMessage request, Boolean async, Boolean doRequestAuth, CancellationToken cancellationToken)
   at System.Net.Http.RedirectHandler.SendAsync(HttpRequestMessage request, Boolean async, CancellationToken cancellationToken)
   at System.Net.Http.HttpClient.<SendAsync>g__Core|83_0(HttpRequestMessage request, HttpCompletionOption completionOption, CancellationTokenSource cts, Boolean disposeCts, CancellationTokenSource pendingRequestsCts, CancellationToken originalCancellationToken)
   at ReportPortal.Client.Resources.ServiceBaseResource.SendHttpRequestAsync[TResponse](HttpMethod httpMethod, String uri, HttpContent httpContent)
   at ReportPortal.Shared.Internal.Delegating.BaseRequestExecuter.ExecuteAsync[T](Func`1 func, Action`1 beforeNextAttemptCallback, IStatisticsCounter statisticsCounter)
   at ReportPortal.Shared.Internal.Delegating.ExponentialRetryRequestExecuter.ExecuteAsync[T](Func`1 func, Action`1 beforeNextAttempt, IStatisticsCounter statisticsCounter)
ExponentialRetryRequestExecuter Error: 0 : 16:45:41.6827628 : 1-vstest.console : Error while invoking '<Start>b__4' method. Current attempt: 1. Waiting 16 seconds and retrying it.
System.Net.Http.HttpRequestException: A connection attempt failed because the connected party did not properly respond after a period of time, or established connection failed because connected host has failed to respond. (192.168.0.154:8080)
 ---> System.Net.Sockets.SocketException (10060): A connection attempt failed because the connected party did not properly respond after a period of time, or established connection failed because connected host has failed to respond.
   at System.Net.Sockets.Socket.AwaitableSocketAsyncEventArgs.ThrowException(SocketError error, CancellationToken cancellationToken)
   at System.Net.Sockets.Socket.AwaitableSocketAsyncEventArgs.System.Threading.Tasks.Sources.IValueTaskSource.GetResult(Int16 token)
   at System.Net.Sockets.Socket.<ConnectAsync>g__WaitForConnectWithCancellation|277_0(AwaitableSocketAsyncEventArgs saea, ValueTask connectTask, CancellationToken cancellationToken)
   at System.Net.Http.HttpConnectionPool.ConnectToTcpHostAsync(String host, Int32 port, HttpRequestMessage initialRequest, Boolean async, CancellationToken cancellationToken)
   --- End of inner exception stack trace ---
   at System.Net.Http.HttpConnectionPool.ConnectToTcpHostAsync(String host, Int32 port, HttpRequestMessage initialRequest, Boolean async, CancellationToken cancellationToken)
   at System.Net.Http.HttpConnectionPool.ConnectAsync(HttpRequestMessage request, Boolean async, CancellationToken cancellationToken)
   at System.Net.Http.HttpConnectionPool.CreateHttp11ConnectionAsync(HttpRequestMessage request, Boolean async, CancellationToken cancellationToken)
   at System.Net.Http.HttpConnectionPool.AddHttp11ConnectionAsync(HttpRequestMessage request)
   at System.Threading.Tasks.TaskCompletionSourceWithCancellation`1.WaitWithCancellationAsync(CancellationToken cancellationToken)
   at System.Net.Http.HttpConnectionPool.GetHttp11ConnectionAsync(HttpRequestMessage request, Boolean async, CancellationToken cancellationToken)
   at System.Net.Http.HttpConnectionPool.SendWithVersionDetectionAndRetryAsync(HttpRequestMessage request, Boolean async, Boolean doRequestAuth, CancellationToken cancellationToken)
   at System.Net.Http.RedirectHandler.SendAsync(HttpRequestMessage request, Boolean async, CancellationToken cancellationToken)
   at System.Net.Http.HttpClient.<SendAsync>g__Core|83_0(HttpRequestMessage request, HttpCompletionOption completionOption, CancellationTokenSource cts, Boolean disposeCts, CancellationTokenSource pendingRequestsCts, CancellationToken originalCancellationToken)
   at ReportPortal.Client.Resources.ServiceBaseResource.SendHttpRequestAsync[TResponse](HttpMethod httpMethod, String uri, HttpContent httpContent)
   at ReportPortal.Shared.Internal.Delegating.BaseRequestExecuter.ExecuteAsync[T](Func`1 func, Action`1 beforeNextAttemptCallback, IStatisticsCounter statisticsCounter)
   at ReportPortal.Shared.Internal.Delegating.ExponentialRetryRequestExecuter.ExecuteAsync[T](Func`1 func, Action`1 beforeNextAttempt, IStatisticsCounter statisticsCounter)
ExponentialRetryRequestExecuter Error: 0 : 16:46:18.7272309 : 1-vstest.console : Error while invoking '<Start>b__4' method. Current attempt: 2.
System.Net.Http.HttpRequestException: A connection attempt failed because the connected party did not properly respond after a period of time, or established connection failed because connected host has failed to respond. (192.168.0.154:8080)
 ---> System.Net.Sockets.SocketException (10060): A connection attempt failed because the connected party did not properly respond after a period of time, or established connection failed because connected host has failed to respond.
   at System.Net.Sockets.Socket.AwaitableSocketAsyncEventArgs.ThrowException(SocketError error, CancellationToken cancellationToken)
   at System.Net.Sockets.Socket.AwaitableSocketAsyncEventArgs.System.Threading.Tasks.Sources.IValueTaskSource.GetResult(Int16 token)
   at System.Net.Sockets.Socket.<ConnectAsync>g__WaitForConnectWithCancellation|277_0(AwaitableSocketAsyncEventArgs saea, ValueTask connectTask, CancellationToken cancellationToken)
   at System.Net.Http.HttpConnectionPool.ConnectToTcpHostAsync(String host, Int32 port, HttpRequestMessage initialRequest, Boolean async, CancellationToken cancellationToken)
   --- End of inner exception stack trace ---
   at System.Net.Http.HttpConnectionPool.ConnectToTcpHostAsync(String host, Int32 port, HttpRequestMessage initialRequest, Boolean async, CancellationToken cancellationToken)
   at System.Net.Http.HttpConnectionPool.ConnectAsync(HttpRequestMessage request, Boolean async, CancellationToken cancellationToken)
   at System.Net.Http.HttpConnectionPool.CreateHttp11ConnectionAsync(HttpRequestMessage request, Boolean async, CancellationToken cancellationToken)
   at System.Net.Http.HttpConnectionPool.AddHttp11ConnectionAsync(HttpRequestMessage request)
   at System.Threading.Tasks.TaskCompletionSourceWithCancellation`1.WaitWithCancellationAsync(CancellationToken cancellationToken)
   at System.Net.Http.HttpConnectionPool.GetHttp11ConnectionAsync(HttpRequestMessage request, Boolean async, CancellationToken cancellationToken)
   at System.Net.Http.HttpConnectionPool.SendWithVersionDetectionAndRetryAsync(HttpRequestMessage request, Boolean async, Boolean doRequestAuth, CancellationToken cancellationToken)
   at System.Net.Http.RedirectHandler.SendAsync(HttpRequestMessage request, Boolean async, CancellationToken cancellationToken)
   at System.Net.Http.HttpClient.<SendAsync>g__Core|83_0(HttpRequestMessage request, HttpCompletionOption completionOption, CancellationTokenSource cts, Boolean disposeCts, CancellationTokenSource pendingRequestsCts, CancellationToken originalCancellationToken)
   at ReportPortal.Client.Resources.ServiceBaseResource.SendHttpRequestAsync[TResponse](HttpMethod httpMethod, String uri, HttpContent httpContent)
   at ReportPortal.Shared.Internal.Delegating.BaseRequestExecuter.ExecuteAsync[T](Func`1 func, Action`1 beforeNextAttemptCallback, IStatisticsCounter statisticsCounter)
   at ReportPortal.Shared.Internal.Delegating.ExponentialRetryRequestExecuter.ExecuteAsync[T](Func`1 func, Action`1 beforeNextAttempt, IStatisticsCounter statisticsCounter)
TestReporter Error: 0 : 16:46:18.7310267 : 1-vstest.console : System.Exception: Cannot start test item due parent failed to start.
 ---> System.AggregateException: One or more errors occurred. (A connection attempt failed because the connected party did not properly respond after a period of time, or established connection failed because connected host has failed to respond. (192.168.0.154:8080))
 ---> System.Net.Http.HttpRequestException: A connection attempt failed because the connected party did not properly respond after a period of time, or established connection failed because connected host has failed to respond. (192.168.0.154:8080)
 ---> System.Net.Sockets.SocketException (10060): A connection attempt failed because the connected party did not properly respond after a period of time, or established connection failed because connected host has failed to respond.
   at System.Net.Sockets.Socket.AwaitableSocketAsyncEventArgs.ThrowException(SocketError error, CancellationToken cancellationToken)
   at System.Net.Sockets.Socket.AwaitableSocketAsyncEventArgs.System.Threading.Tasks.Sources.IValueTaskSource.GetResult(Int16 token)
   at System.Net.Sockets.Socket.<ConnectAsync>g__WaitForConnectWithCancellation|277_0(AwaitableSocketAsyncEventArgs saea, ValueTask connectTask, CancellationToken cancellationToken)
   at System.Net.Http.HttpConnectionPool.ConnectToTcpHostAsync(String host, Int32 port, HttpRequestMessage initialRequest, Boolean async, CancellationToken cancellationToken)
   --- End of inner exception stack trace ---
   at System.Net.Http.HttpConnectionPool.ConnectToTcpHostAsync(String host, Int32 port, HttpRequestMessage initialRequest, Boolean async, CancellationToken cancellationToken)
   at System.Net.Http.HttpConnectionPool.ConnectAsync(HttpRequestMessage request, Boolean async, CancellationToken cancellationToken)
   at System.Net.Http.HttpConnectionPool.CreateHttp11ConnectionAsync(HttpRequestMessage request, Boolean async, CancellationToken cancellationToken)
   at System.Net.Http.HttpConnectionPool.AddHttp11ConnectionAsync(HttpRequestMessage request)
   at System.Threading.Tasks.TaskCompletionSourceWithCancellation`1.WaitWithCancellationAsync(CancellationToken cancellationToken)
   at System.Net.Http.HttpConnectionPool.GetHttp11ConnectionAsync(HttpRequestMessage request, Boolean async, CancellationToken cancellationToken)
   at System.Net.Http.HttpConnectionPool.SendWithVersionDetectionAndRetryAsync(HttpRequestMessage request, Boolean async, Boolean doRequestAuth, CancellationToken cancellationToken)
   at System.Net.Http.RedirectHandler.SendAsync(HttpRequestMessage request, Boolean async, CancellationToken cancellationToken)
   at System.Net.Http.HttpClient.<SendAsync>g__Core|83_0(HttpRequestMessage request, HttpCompletionOption completionOption, CancellationTokenSource cts, Boolean disposeCts, CancellationTokenSource pendingRequestsCts, CancellationToken originalCancellationToken)
   at ReportPortal.Client.Resources.ServiceBaseResource.SendHttpRequestAsync[TResponse](HttpMethod httpMethod, String uri, HttpContent httpContent)
   at ReportPortal.Shared.Internal.Delegating.BaseRequestExecuter.ExecuteAsync[T](Func`1 func, Action`1 beforeNextAttemptCallback, IStatisticsCounter statisticsCounter)
   at ReportPortal.Shared.Internal.Delegating.ExponentialRetryRequestExecuter.ExecuteAsync[T](Func`1 func, Action`1 beforeNextAttempt, IStatisticsCounter statisticsCounter)
   at ReportPortal.Shared.Internal.Delegating.ExponentialRetryRequestExecuter.ExecuteAsync[T](Func`1 func, Action`1 beforeNextAttempt, IStatisticsCounter statisticsCounter)
   at ReportPortal.Shared.Reporter.LaunchReporter.<>c__DisplayClass25_0.<<Start>b__1>d.MoveNext()
   --- End of inner exception stack trace ---
   --- End of inner exception stack trace ---
TestReporter Error: 0 : 16:46:18.7385429 : 1-vstest.console : System.Exception: Cannot start test item due parent failed to start.
 ---> System.AggregateException: One or more errors occurred. (Cannot start test item due parent failed to start.)
 ---> System.Exception: Cannot start test item due parent failed to start.
 ---> System.AggregateException: One or more errors occurred. (A connection attempt failed because the connected party did not properly respond after a period of time, or established connection failed because connected host has failed to respond. (192.168.0.154:8080))
 ---> System.Net.Http.HttpRequestException: A connection attempt failed because the connected party did not properly respond after a period of time, or established connection failed because connected host has failed to respond. (192.168.0.154:8080)
 ---> System.Net.Sockets.SocketException (10060): A connection attempt failed because the connected party did not properly respond after a period of time, or established connection failed because connected host has failed to respond.
   at System.Net.Sockets.Socket.AwaitableSocketAsyncEventArgs.ThrowException(SocketError error, CancellationToken cancellationToken)
   at System.Net.Sockets.Socket.AwaitableSocketAsyncEventArgs.System.Threading.Tasks.Sources.IValueTaskSource.GetResult(Int16 token)
   at System.Net.Sockets.Socket.<ConnectAsync>g__WaitForConnectWithCancellation|277_0(AwaitableSocketAsyncEventArgs saea, ValueTask connectTask, CancellationToken cancellationToken)
   at System.Net.Http.HttpConnectionPool.ConnectToTcpHostAsync(String host, Int32 port, HttpRequestMessage initialRequest, Boolean async, CancellationToken cancellationToken)
   --- End of inner exception stack trace ---
   at System.Net.Http.HttpConnectionPool.ConnectToTcpHostAsync(String host, Int32 port, HttpRequestMessage initialRequest, Boolean async, CancellationToken cancellationToken)
   at System.Net.Http.HttpConnectionPool.ConnectAsync(HttpRequestMessage request, Boolean async, CancellationToken cancellationToken)
   at System.Net.Http.HttpConnectionPool.CreateHttp11ConnectionAsync(HttpRequestMessage request, Boolean async, CancellationToken cancellationToken)
   at System.Net.Http.HttpConnectionPool.AddHttp11ConnectionAsync(HttpRequestMessage request)
   at System.Threading.Tasks.TaskCompletionSourceWithCancellation`1.WaitWithCancellationAsync(CancellationToken cancellationToken)
   at System.Net.Http.HttpConnectionPool.GetHttp11ConnectionAsync(HttpRequestMessage request, Boolean async, CancellationToken cancellationToken)
   at System.Net.Http.HttpConnectionPool.SendWithVersionDetectionAndRetryAsync(HttpRequestMessage request, Boolean async, Boolean doRequestAuth, CancellationToken cancellationToken)
   at System.Net.Http.RedirectHandler.SendAsync(HttpRequestMessage request, Boolean async, CancellationToken cancellationToken)
   at System.Net.Http.HttpClient.<SendAsync>g__Core|83_0(HttpRequestMessage request, HttpCompletionOption completionOption, CancellationTokenSource cts, Boolean disposeCts, CancellationTokenSource pendingRequestsCts, CancellationToken originalCancellationToken)
   at ReportPortal.Client.Resources.ServiceBaseResource.SendHttpRequestAsync[TResponse](HttpMethod httpMethod, String uri, HttpContent httpContent)
   at ReportPortal.Shared.Internal.Delegating.BaseRequestExecuter.ExecuteAsync[T](Func`1 func, Action`1 beforeNextAttemptCallback, IStatisticsCounter statisticsCounter)
   at ReportPortal.Shared.Internal.Delegating.ExponentialRetryRequestExecuter.ExecuteAsync[T](Func`1 func, Action`1 beforeNextAttempt, IStatisticsCounter statisticsCounter)
   at ReportPortal.Shared.Internal.Delegating.ExponentialRetryRequestExecuter.ExecuteAsync[T](Func`1 func, Action`1 beforeNextAttempt, IStatisticsCounter statisticsCounter)
   at ReportPortal.Shared.Reporter.LaunchReporter.<>c__DisplayClass25_0.<<Start>b__1>d.MoveNext()
   --- End of inner exception stack trace ---
   --- End of inner exception stack trace ---
   at ReportPortal.Shared.Reporter.TestReporter.<>c__DisplayClass24_0.<<Start>b__0>d.MoveNext()
   --- End of inner exception stack trace ---
   --- End of inner exception stack trace ---
TestReporter Error: 0 : 16:46:18.7410441 : 1-vstest.console : System.Exception: Cannot start test item due parent failed to start.
 ---> System.AggregateException: One or more errors occurred. (Cannot start test item due parent failed to start.)
 ---> System.Exception: Cannot start test item due parent failed to start.
 ---> System.AggregateException: One or more errors occurred. (Cannot start test item due parent failed to start.)
 ---> System.Exception: Cannot start test item due parent failed to start.
 ---> System.AggregateException: One or more errors occurred. (A connection attempt failed because the connected party did not properly respond after a period of time, or established connection failed because connected host has failed to respond. (192.168.0.154:8080))
 ---> System.Net.Http.HttpRequestException: A connection attempt failed because the connected party did not properly respond after a period of time, or established connection failed because connected host has failed to respond. (192.168.0.154:8080)
 ---> System.Net.Sockets.SocketException (10060): A connection attempt failed because the connected party did not properly respond after a period of time, or established connection failed because connected host has failed to respond.
   at System.Net.Sockets.Socket.AwaitableSocketAsyncEventArgs.ThrowException(SocketError error, CancellationToken cancellationToken)
   at System.Net.Sockets.Socket.AwaitableSocketAsyncEventArgs.System.Threading.Tasks.Sources.IValueTaskSource.GetResult(Int16 token)
   at System.Net.Sockets.Socket.<ConnectAsync>g__WaitForConnectWithCancellation|277_0(AwaitableSocketAsyncEventArgs saea, ValueTask connectTask, CancellationToken cancellationToken)
   at System.Net.Http.HttpConnectionPool.ConnectToTcpHostAsync(String host, Int32 port, HttpRequestMessage initialRequest, Boolean async, CancellationToken cancellationToken)
   --- End of inner exception stack trace ---
   at System.Net.Http.HttpConnectionPool.ConnectToTcpHostAsync(String host, Int32 port, HttpRequestMessage initialRequest, Boolean async, CancellationToken cancellationToken)
   at System.Net.Http.HttpConnectionPool.ConnectAsync(HttpRequestMessage request, Boolean async, CancellationToken cancellationToken)
   at System.Net.Http.HttpConnectionPool.CreateHttp11ConnectionAsync(HttpRequestMessage request, Boolean async, CancellationToken cancellationToken)
   at System.Net.Http.HttpConnectionPool.AddHttp11ConnectionAsync(HttpRequestMessage request)
   at System.Threading.Tasks.TaskCompletionSourceWithCancellation`1.WaitWithCancellationAsync(CancellationToken cancellationToken)
   at System.Net.Http.HttpConnectionPool.GetHttp11ConnectionAsync(HttpRequestMessage request, Boolean async, CancellationToken cancellationToken)
   at System.Net.Http.HttpConnectionPool.SendWithVersionDetectionAndRetryAsync(HttpRequestMessage request, Boolean async, Boolean doRequestAuth, CancellationToken cancellationToken)
   at System.Net.Http.RedirectHandler.SendAsync(HttpRequestMessage request, Boolean async, CancellationToken cancellationToken)
   at System.Net.Http.HttpClient.<SendAsync>g__Core|83_0(HttpRequestMessage request, HttpCompletionOption completionOption, CancellationTokenSource cts, Boolean disposeCts, CancellationTokenSource pendingRequestsCts, CancellationToken originalCancellationToken)
   at ReportPortal.Client.Resources.ServiceBaseResource.SendHttpRequestAsync[TResponse](HttpMethod httpMethod, String uri, HttpContent httpContent)
   at ReportPortal.Shared.Internal.Delegating.BaseRequestExecuter.ExecuteAsync[T](Func`1 func, Action`1 beforeNextAttemptCallback, IStatisticsCounter statisticsCounter)
   at ReportPortal.Shared.Internal.Delegating.ExponentialRetryRequestExecuter.ExecuteAsync[T](Func`1 func, Action`1 beforeNextAttempt, IStatisticsCounter statisticsCounter)
   at ReportPortal.Shared.Internal.Delegating.ExponentialRetryRequestExecuter.ExecuteAsync[T](Func`1 func, Action`1 beforeNextAttempt, IStatisticsCounter statisticsCounter)
   at ReportPortal.Shared.Reporter.LaunchReporter.<>c__DisplayClass25_0.<<Start>b__1>d.MoveNext()
   --- End of inner exception stack trace ---
   --- End of inner exception stack trace ---
   at ReportPortal.Shared.Reporter.TestReporter.<>c__DisplayClass24_0.<<Start>b__0>d.MoveNext()
   --- End of inner exception stack trace ---
   --- End of inner exception stack trace ---
   at ReportPortal.Shared.Reporter.TestReporter.<>c__DisplayClass24_0.<<Start>b__0>d.MoveNext()
   --- End of inner exception stack trace ---
   --- End of inner exception stack trace ---
TestReporter Error: 0 : 16:46:18.7475918 : 1-vstest.console : System.Exception: Cannot finish test item due starting item failed.
 ---> System.AggregateException: One or more errors occurred. (Cannot start test item due parent failed to start.)
 ---> System.Exception: Cannot start test item due parent failed to start.
 ---> System.AggregateException: One or more errors occurred. (Cannot start test item due parent failed to start.)
 ---> System.Exception: Cannot start test item due parent failed to start.
 ---> System.AggregateException: One or more errors occurred. (Cannot start test item due parent failed to start.)
 ---> System.Exception: Cannot start test item due parent failed to start.
 ---> System.AggregateException: One or more errors occurred. (A connection attempt failed because the connected party did not properly respond after a period of time, or established connection failed because connected host has failed to respond. (192.168.0.154:8080))
 ---> System.Net.Http.HttpRequestException: A connection attempt failed because the connected party did not properly respond after a period of time, or established connection failed because connected host has failed to respond. (192.168.0.154:8080)
 ---> System.Net.Sockets.SocketException (10060): A connection attempt failed because the connected party did not properly respond after a period of time, or established connection failed because connected host has failed to respond.
   at System.Net.Sockets.Socket.AwaitableSocketAsyncEventArgs.ThrowException(SocketError error, CancellationToken cancellationToken)
   at System.Net.Sockets.Socket.AwaitableSocketAsyncEventArgs.System.Threading.Tasks.Sources.IValueTaskSource.GetResult(Int16 token)
   at System.Net.Sockets.Socket.<ConnectAsync>g__WaitForConnectWithCancellation|277_0(AwaitableSocketAsyncEventArgs saea, ValueTask connectTask, CancellationToken cancellationToken)
   at System.Net.Http.HttpConnectionPool.ConnectToTcpHostAsync(String host, Int32 port, HttpRequestMessage initialRequest, Boolean async, CancellationToken cancellationToken)
   --- End of inner exception stack trace ---
   at System.Net.Http.HttpConnectionPool.ConnectToTcpHostAsync(String host, Int32 port, HttpRequestMessage initialRequest, Boolean async, CancellationToken cancellationToken)
   at System.Net.Http.HttpConnectionPool.ConnectAsync(HttpRequestMessage request, Boolean async, CancellationToken cancellationToken)
   at System.Net.Http.HttpConnectionPool.CreateHttp11ConnectionAsync(HttpRequestMessage request, Boolean async, CancellationToken cancellationToken)
   at System.Net.Http.HttpConnectionPool.AddHttp11ConnectionAsync(HttpRequestMessage request)
   at System.Threading.Tasks.TaskCompletionSourceWithCancellation`1.WaitWithCancellationAsync(CancellationToken cancellationToken)
   at System.Net.Http.HttpConnectionPool.GetHttp11ConnectionAsync(HttpRequestMessage request, Boolean async, CancellationToken cancellationToken)
   at System.Net.Http.HttpConnectionPool.SendWithVersionDetectionAndRetryAsync(HttpRequestMessage request, Boolean async, Boolean doRequestAuth, CancellationToken cancellationToken)
   at System.Net.Http.RedirectHandler.SendAsync(HttpRequestMessage request, Boolean async, CancellationToken cancellationToken)
   at System.Net.Http.HttpClient.<SendAsync>g__Core|83_0(HttpRequestMessage request, HttpCompletionOption completionOption, CancellationTokenSource cts, Boolean disposeCts, CancellationTokenSource pendingRequestsCts, CancellationToken originalCancellationToken)
   at ReportPortal.Client.Resources.ServiceBaseResource.SendHttpRequestAsync[TResponse](HttpMethod httpMethod, String uri, HttpContent httpContent)
   at ReportPortal.Shared.Internal.Delegating.BaseRequestExecuter.ExecuteAsync[T](Func`1 func, Action`1 beforeNextAttemptCallback, IStatisticsCounter statisticsCounter)
   at ReportPortal.Shared.Internal.Delegating.ExponentialRetryRequestExecuter.ExecuteAsync[T](Func`1 func, Action`1 beforeNextAttempt, IStatisticsCounter statisticsCounter)
   at ReportPortal.Shared.Internal.Delegating.ExponentialRetryRequestExecuter.ExecuteAsync[T](Func`1 func, Action`1 beforeNextAttempt, IStatisticsCounter statisticsCounter)
   at ReportPortal.Shared.Reporter.LaunchReporter.<>c__DisplayClass25_0.<<Start>b__1>d.MoveNext()
   --- End of inner exception stack trace ---
   --- End of inner exception stack trace ---
   at ReportPortal.Shared.Reporter.TestReporter.<>c__DisplayClass24_0.<<Start>b__0>d.MoveNext()
   --- End of inner exception stack trace ---
   --- End of inner exception stack trace ---
   at ReportPortal.Shared.Reporter.TestReporter.<>c__DisplayClass24_0.<<Start>b__0>d.MoveNext()
   --- End of inner exception stack trace ---
   --- End of inner exception stack trace ---
   at ReportPortal.Shared.Reporter.TestReporter.<>c__DisplayClass24_0.<<Start>b__0>d.MoveNext()
   --- End of inner exception stack trace ---
   --- End of inner exception stack trace ---
TestReporter Error: 0 : 16:46:19.5305938 : 1-vstest.console : System.Exception: Cannot finish test item due starting item failed.
 ---> System.AggregateException: One or more errors occurred. (Cannot start test item due parent failed to start.)
 ---> System.Exception: Cannot start test item due parent failed to start.
 ---> System.AggregateException: One or more errors occurred. (Cannot start test item due parent failed to start.)
 ---> System.Exception: Cannot start test item due parent failed to start.
 ---> System.AggregateException: One or more errors occurred. (A connection attempt failed because the connected party did not properly respond after a period of time, or established connection failed because connected host has failed to respond. (192.168.0.154:8080))
 ---> System.Net.Http.HttpRequestException: A connection attempt failed because the connected party did not properly respond after a period of time, or established connection failed because connected host has failed to respond. (192.168.0.154:8080)
 ---> System.Net.Sockets.SocketException (10060): A connection attempt failed because the connected party did not properly respond after a period of time, or established connection failed because connected host has failed to respond.
   at System.Net.Sockets.Socket.AwaitableSocketAsyncEventArgs.ThrowException(SocketError error, CancellationToken cancellationToken)
   at System.Net.Sockets.Socket.AwaitableSocketAsyncEventArgs.System.Threading.Tasks.Sources.IValueTaskSource.GetResult(Int16 token)
   at System.Net.Sockets.Socket.<ConnectAsync>g__WaitForConnectWithCancellation|277_0(AwaitableSocketAsyncEventArgs saea, ValueTask connectTask, CancellationToken cancellationToken)
   at System.Net.Http.HttpConnectionPool.ConnectToTcpHostAsync(String host, Int32 port, HttpRequestMessage initialRequest, Boolean async, CancellationToken cancellationToken)
   --- End of inner exception stack trace ---
   at System.Net.Http.HttpConnectionPool.ConnectToTcpHostAsync(String host, Int32 port, HttpRequestMessage initialRequest, Boolean async, CancellationToken cancellationToken)
   at System.Net.Http.HttpConnectionPool.ConnectAsync(HttpRequestMessage request, Boolean async, CancellationToken cancellationToken)
   at System.Net.Http.HttpConnectionPool.CreateHttp11ConnectionAsync(HttpRequestMessage request, Boolean async, CancellationToken cancellationToken)
   at System.Net.Http.HttpConnectionPool.AddHttp11ConnectionAsync(HttpRequestMessage request)
   at System.Threading.Tasks.TaskCompletionSourceWithCancellation`1.WaitWithCancellationAsync(CancellationToken cancellationToken)
   at System.Net.Http.HttpConnectionPool.GetHttp11ConnectionAsync(HttpRequestMessage request, Boolean async, CancellationToken cancellationToken)
   at System.Net.Http.HttpConnectionPool.SendWithVersionDetectionAndRetryAsync(HttpRequestMessage request, Boolean async, Boolean doRequestAuth, CancellationToken cancellationToken)
   at System.Net.Http.RedirectHandler.SendAsync(HttpRequestMessage request, Boolean async, CancellationToken cancellationToken)
   at System.Net.Http.HttpClient.<SendAsync>g__Core|83_0(HttpRequestMessage request, HttpCompletionOption completionOption, CancellationTokenSource cts, Boolean disposeCts, CancellationTokenSource pendingRequestsCts, CancellationToken originalCancellationToken)
   at ReportPortal.Client.Resources.ServiceBaseResource.SendHttpRequestAsync[TResponse](HttpMethod httpMethod, String uri, HttpContent httpContent)
   at ReportPortal.Shared.Internal.Delegating.BaseRequestExecuter.ExecuteAsync[T](Func`1 func, Action`1 beforeNextAttemptCallback, IStatisticsCounter statisticsCounter)
   at ReportPortal.Shared.Internal.Delegating.ExponentialRetryRequestExecuter.ExecuteAsync[T](Func`1 func, Action`1 beforeNextAttempt, IStatisticsCounter statisticsCounter)
   at ReportPortal.Shared.Internal.Delegating.ExponentialRetryRequestExecuter.ExecuteAsync[T](Func`1 func, Action`1 beforeNextAttempt, IStatisticsCounter statisticsCounter)
   at ReportPortal.Shared.Reporter.LaunchReporter.<>c__DisplayClass25_0.<<Start>b__1>d.MoveNext()
   --- End of inner exception stack trace ---
   --- End of inner exception stack trace ---
   at ReportPortal.Shared.Reporter.TestReporter.<>c__DisplayClass24_0.<<Start>b__0>d.MoveNext()
   --- End of inner exception stack trace ---
   --- End of inner exception stack trace ---
   at ReportPortal.Shared.Reporter.TestReporter.<>c__DisplayClass24_0.<<Start>b__0>d.MoveNext()
   --- End of inner exception stack trace ---
   --- End of inner exception stack trace ---
TestReporter Error: 0 : 16:46:19.5341825 : 1-vstest.console : System.Exception: Cannot finish test item due starting item failed.
 ---> System.AggregateException: One or more errors occurred. (Cannot start test item due parent failed to start.)
 ---> System.Exception: Cannot start test item due parent failed to start.
 ---> System.AggregateException: One or more errors occurred. (A connection attempt failed because the connected party did not properly respond after a period of time, or established connection failed because connected host has failed to respond. (192.168.0.154:8080))
 ---> System.Net.Http.HttpRequestException: A connection attempt failed because the connected party did not properly respond after a period of time, or established connection failed because connected host has failed to respond. (192.168.0.154:8080)
 ---> System.Net.Sockets.SocketException (10060): A connection attempt failed because the connected party did not properly respond after a period of time, or established connection failed because connected host has failed to respond.
   at System.Net.Sockets.Socket.AwaitableSocketAsyncEventArgs.ThrowException(SocketError error, CancellationToken cancellationToken)
   at System.Net.Sockets.Socket.AwaitableSocketAsyncEventArgs.System.Threading.Tasks.Sources.IValueTaskSource.GetResult(Int16 token)
   at System.Net.Sockets.Socket.<ConnectAsync>g__WaitForConnectWithCancellation|277_0(AwaitableSocketAsyncEventArgs saea, ValueTask connectTask, CancellationToken cancellationToken)
   at System.Net.Http.HttpConnectionPool.ConnectToTcpHostAsync(String host, Int32 port, HttpRequestMessage initialRequest, Boolean async, CancellationToken cancellationToken)
   --- End of inner exception stack trace ---
   at System.Net.Http.HttpConnectionPool.ConnectToTcpHostAsync(String host, Int32 port, HttpRequestMessage initialRequest, Boolean async, CancellationToken cancellationToken)
   at System.Net.Http.HttpConnectionPool.ConnectAsync(HttpRequestMessage request, Boolean async, CancellationToken cancellationToken)
   at System.Net.Http.HttpConnectionPool.CreateHttp11ConnectionAsync(HttpRequestMessage request, Boolean async, CancellationToken cancellationToken)
   at System.Net.Http.HttpConnectionPool.AddHttp11ConnectionAsync(HttpRequestMessage request)
   at System.Threading.Tasks.TaskCompletionSourceWithCancellation`1.WaitWithCancellationAsync(CancellationToken cancellationToken)
   at System.Net.Http.HttpConnectionPool.GetHttp11ConnectionAsync(HttpRequestMessage request, Boolean async, CancellationToken cancellationToken)
   at System.Net.Http.HttpConnectionPool.SendWithVersionDetectionAndRetryAsync(HttpRequestMessage request, Boolean async, Boolean doRequestAuth, CancellationToken cancellationToken)
   at System.Net.Http.RedirectHandler.SendAsync(HttpRequestMessage request, Boolean async, CancellationToken cancellationToken)
   at System.Net.Http.HttpClient.<SendAsync>g__Core|83_0(HttpRequestMessage request, HttpCompletionOption completionOption, CancellationTokenSource cts, Boolean disposeCts, CancellationTokenSource pendingRequestsCts, CancellationToken originalCancellationToken)
   at ReportPortal.Client.Resources.ServiceBaseResource.SendHttpRequestAsync[TResponse](HttpMethod httpMethod, String uri, HttpContent httpContent)
   at ReportPortal.Shared.Internal.Delegating.BaseRequestExecuter.ExecuteAsync[T](Func`1 func, Action`1 beforeNextAttemptCallback, IStatisticsCounter statisticsCounter)
   at ReportPortal.Shared.Internal.Delegating.ExponentialRetryRequestExecuter.ExecuteAsync[T](Func`1 func, Action`1 beforeNextAttempt, IStatisticsCounter statisticsCounter)
   at ReportPortal.Shared.Internal.Delegating.ExponentialRetryRequestExecuter.ExecuteAsync[T](Func`1 func, Action`1 beforeNextAttempt, IStatisticsCounter statisticsCounter)
   at ReportPortal.Shared.Reporter.LaunchReporter.<>c__DisplayClass25_0.<<Start>b__1>d.MoveNext()
--- End of stack trace from previous location ---
   at ReportPortal.Shared.Reporter.LaunchReporter.Sync()
   at ReportPortal.VSTest.TestLogger.ReportPortalLogger.Events_TestRunComplete(Object sender, TestRunCompleteEventArgs e) in C:\projects\agent-net-vstest\src\ReportPortal.VSTest.TestLogger\ReportPortalLogger.cs:line 451
   --- End of inner exception stack trace ---
   --- End of inner exception stack trace ---
   at ReportPortal.Shared.Reporter.TestReporter.<>c__DisplayClass24_0.<<Start>b__0>d.MoveNext()
   --- End of inner exception stack trace ---
   --- End of inner exception stack trace ---
LaunchReporter Error: 0 : 16:46:19.5397502 : 1-vstest.console : System.Exception: Cannot finish launch due starting launch failed.
 ---> System.AggregateException: One or more errors occurred. (A connection attempt failed because the connected party did not properly respond after a period of time, or established connection failed because connected host has failed to respond. (192.168.0.154:8080))
 ---> System.Net.Http.HttpRequestException: A connection attempt failed because the connected party did not properly respond after a period of time, or established connection failed because connected host has failed to respond. (192.168.0.154:8080)
 ---> System.Net.Sockets.SocketException (10060): A connection attempt failed because the connected party did not properly respond after a period of time, or established connection failed because connected host has failed to respond.
   at System.Net.Sockets.Socket.AwaitableSocketAsyncEventArgs.ThrowException(SocketError error, CancellationToken cancellationToken)
   at System.Net.Sockets.Socket.AwaitableSocketAsyncEventArgs.System.Threading.Tasks.Sources.IValueTaskSource.GetResult(Int16 token)
   at System.Net.Sockets.Socket.<ConnectAsync>g__WaitForConnectWithCancellation|277_0(AwaitableSocketAsyncEventArgs saea, ValueTask connectTask, CancellationToken cancellationToken)
   at System.Net.Http.HttpConnectionPool.ConnectToTcpHostAsync(String host, Int32 port, HttpRequestMessage initialRequest, Boolean async, CancellationToken cancellationToken)
   --- End of inner exception stack trace ---
   at System.Net.Http.HttpConnectionPool.ConnectToTcpHostAsync(String host, Int32 port, HttpRequestMessage initialRequest, Boolean async, CancellationToken cancellationToken)
   at System.Net.Http.HttpConnectionPool.ConnectAsync(HttpRequestMessage request, Boolean async, CancellationToken cancellationToken)
   at System.Net.Http.HttpConnectionPool.CreateHttp11ConnectionAsync(HttpRequestMessage request, Boolean async, CancellationToken cancellationToken)
   at System.Net.Http.HttpConnectionPool.AddHttp11ConnectionAsync(HttpRequestMessage request)
   at System.Threading.Tasks.TaskCompletionSourceWithCancellation`1.WaitWithCancellationAsync(CancellationToken cancellationToken)
   at System.Net.Http.HttpConnectionPool.GetHttp11ConnectionAsync(HttpRequestMessage request, Boolean async, CancellationToken cancellationToken)
   at System.Net.Http.HttpConnectionPool.SendWithVersionDetectionAndRetryAsync(HttpRequestMessage request, Boolean async, Boolean doRequestAuth, CancellationToken cancellationToken)
   at System.Net.Http.RedirectHandler.SendAsync(HttpRequestMessage request, Boolean async, CancellationToken cancellationToken)
   at System.Net.Http.HttpClient.<SendAsync>g__Core|83_0(HttpRequestMessage request, HttpCompletionOption completionOption, CancellationTokenSource cts, Boolean disposeCts, CancellationTokenSource pendingRequestsCts, CancellationToken originalCancellationToken)
   at ReportPortal.Client.Resources.ServiceBaseResource.SendHttpRequestAsync[TResponse](HttpMethod httpMethod, String uri, HttpContent httpContent)
   at ReportPortal.Shared.Internal.Delegating.BaseRequestExecuter.ExecuteAsync[T](Func`1 func, Action`1 beforeNextAttemptCallback, IStatisticsCounter statisticsCounter)
   at ReportPortal.Shared.Internal.Delegating.ExponentialRetryRequestExecuter.ExecuteAsync[T](Func`1 func, Action`1 beforeNextAttempt, IStatisticsCounter statisticsCounter)
   at ReportPortal.Shared.Internal.Delegating.ExponentialRetryRequestExecuter.ExecuteAsync[T](Func`1 func, Action`1 beforeNextAttempt, IStatisticsCounter statisticsCounter)
   at ReportPortal.Shared.Reporter.LaunchReporter.<>c__DisplayClass25_0.<<Start>b__1>d.MoveNext()
--- End of stack trace from previous location ---
   at ReportPortal.Shared.Reporter.LaunchReporter.Sync()
   at ReportPortal.VSTest.TestLogger.ReportPortalLogger.Events_TestRunComplete(Object sender, TestRunCompleteEventArgs e) in C:\projects\agent-net-vstest\src\ReportPortal.VSTest.TestLogger\ReportPortalLogger.cs:line 451
   --- End of inner exception stack trace ---
   --- End of inner exception stack trace ---
